Workbook

Sheet INSTRUCOES
B3: ATENÇÃO
B5: Altere apenas a aba ResultadosObtidos preenchendo as células azuis.
B6: Se não tiver resultados da literatura, deixe a célula em branco.
B7: Você deve preencher toda a tabela uma vez com o melhor resultado e,
B8: depois, toda a tabela novamente com o valor da média das execuções de cada algoritmo.
B10: Na aba DesvioPercentual você consegue observar os valores de desvio.
B11: Nesta aba, ao lado direito da tabela, tem uma interpretação dos dados, bem como as médias.
B13: Na aba Desvio_Latex você encontra o código em latex das linhas das instâncias para colar na tabela.
B14: Você precisa informar o número de casas decimais desejado.
B15: O código em latex já coloca os dados em negrito automaticamente.
B16: Se você não tiver inserido dados da literatura, o código em latex não vai conter a coluna
B17: e você vai precisar utilizar a versão da tabela sem essa coluna.

Sheet ResultadosObtidos
B3: Tabela 1: Resultados obtidos pelos algoritmos
B4: Instâncias | C4: best | D4: Literatura | E4: Guloso | F4: Randomizado | I4: Reativo {0,2; 0,3; 0,4}
F5: alfa = 0,2 | G5: alfa = 0,3 | H5: alfa = 0,4
B6: nome instancia 1 | C6: =MIN(E6:I6) -> 100 | D6: 102 | E6: 100 | F6: 110 | G6: 120 | H6: 130 | I6: 140
B7: nome instancia 2 | C7: =MIN(E7:I7) -> 36 | D7: 37 | E7: 36 | F7: 73 | G7: 61 | H7: 80 | I7: 69
B8: nome instancia 3 | C8: =MIN(E8:I8) -> 30 | D8: 33 | E8: 77 | F8: 53 | G8: 30 | H8: 77 | I8: 74
B9: nome instancia 4 | C9: =MIN(E9:I9) -> 44 | D9: 44 | E9: 44 | F9: 65 | G9: 76 | H9: 66 | I9: 79
B10: nome instancia 5 | C10: =MIN(E10:I10) -> 33 | D10: 34 | E10: 60 | F10: 57 | G10: 60 | H10: 33 | I10: 47
B11: nome instancia 6 | C11: =MIN(E11:I11) -> 34 | D11: 45 | E11: 75 | F11: 50 | G11: 71 | H11: 34 | I11: 53
B12: nome instancia 7 | C12: =MIN(E12:I12) -> 48 | D12: 49 | E12: 53 | F12: 48 | G12: 63 | H12: 58 | I12: 56
B13: nome instancia 8 | C13: =MIN(E13:I13) -> 44 | D13: 44 | E13: 44 | F13: 67 | G13: 70 | H13: 45 | I13: 47
B14: nome instancia 9 | C14: =MIN(E14:I14) -> 35 | D14: 35 | E14: 41 | F14: 62 | G14: 54 | H14: 37 | I14: 35
B15: nome instancia 10 | C15: =MIN(E15:I15) -> 36 | D15: 37 | E15: 36 | F15: 77 | G15: 51 | H15: 43 | I15: 47
B16: nome instancia 11 | C16: =MIN(E16:I16) -> 38 | D16: 38 | E16: 46 | F16: 75 | G16: 75 | H16: 38 | I16: 48
B17: nome instancia 12 | C17: =MIN(E17:I17) -> 32 | D17: 33 | E17: 62 | F17: 45 | G17: 32 | H17: 40 | I17: 53
... B35: nome instancia 30 | C35: =MIN(E35:I35) -> 35 | D35: 36 | E35: 41 | F35: 62 | G35: 54 | H35: 37 | I35: 35

Sheet DesvioPercentual
K2: Com esses dados fictícios, a melhor abordagem implementada é a Reativa, que apresentou resultados mais próximos da melhor solução (best). Quando aparece 0% na coluna de um algoritmo, isso indica que, para aquela instância, o algoritmo encontrou o melhor resultado.
B3: Tabela 2: Desvio percentual em relação a melhor solução (best)
B4: Instâncias | C4: best | D4: Literatura | E4: Guloso | F4: Randomizado | I4: Reativo {0,2; 0,3; 0,4} | L4: Instâncias | M4: best | N4: literatura | O4: Guloso | P4: Randomizado | S4: Reativo {0,2; 0,3; 0,4}
F5: alfa = 0,2 | G5: alfa = 0,3 | H5: alfa = 0,4 | P5: alfa = 0,2 | Q5: alfa = 0,3 | R5: alfa = 0,4
B6: =ResultadosObtidos!B6 -> nome instancia 1 | C6: =ResultadosObtidos!C6 -> 100 | D6: =IF(ISBLANK(ResultadosObtidos!D6),"",(ResultadosObtidos!D6-$C6)/$C6) -> 0.02 | E6: =(ResultadosObtidos!E6-$C6)/$C6 -> 0 | F6: =(ResultadosObtidos!F6-$C6)/$C6 -> 0.1 | G6: =(ResultadosObtidos!G6-$C6)/$C6 -> 0.2 | H6: =(ResultadosObtidos!H6-$C6)/$C6 -> 0.3 | I6: =(ResultadosObtidos!I6-$C6)/$C6 -> 0.4 | L6: Média | N6: =AVERAGE(D6:D35) -> 0.038300752 | O6: =AVERAGE(E6:E35) -> 0.31890111 | P6: =AVERAGE(F6:F35) -> 0.63313994 | Q6: =AVERAGE(G6:G35) -> 0.47978857 | R6: =AVERAGE(H6:H35) -> 0.27114615 | S6: =AVERAGE(I6:I35) -> 0.23677453
B7: =ResultadosObtidos!B7 -> nome instancia 2 | C7: =ResultadosObtidos!C7 -> 36 | D7: =IF(ISBLANK(ResultadosObtidos!D7),"",(ResultadosObtidos!D7-$C7)/$C7) -> 0.027777778 | E7: =(ResultadosObtidos!E7-$C7)/$C7 -> 0 | F7: =(ResultadosObtidos!F7-$C7)/$C7 -> 1.0277778 | G7: =(ResultadosObtidos!G7-$C7)/$C7 -> 0.69444444 | H7: =(ResultadosObtidos!H7-$C7)/$C7 -> 1.2222222 | I7: =(ResultadosObtidos!I7-$C7)/$C7 -> 0.91666667
B8: =ResultadosObtidos!B8 -> nome instancia 3 | C8: =ResultadosObtidos!C8 -> 30 | D8: =IF(ISBLANK(ResultadosObtidos!D8),"",(ResultadosObtidos!D8-$C8)/$C8) -> 0.1 | E8: =(ResultadosObtidos!E8-$C8)/$C8 -> 1.5666667 | F8: =(ResultadosObtidos!F8-$C8)/$C8 -> 0.76666667 | G8: =(ResultadosObtidos!G8-$C8)/$C8 -> 0 | H8: =(ResultadosObtidos!H8-$C8)/$C8 -> 1.5666667 | I8: =(ResultadosObtidos!I8-$C8)/$C8 -> 1.4666667
B9: =ResultadosObtidos!B9 -> nome instancia 4 | C9: =ResultadosObtidos!C9 -> 44 | D9: =IF(ISBLANK(ResultadosObtidos!D9),"",(ResultadosObtidos!D9-$C9)/$C9) -> 0 | E9: =(ResultadosObtidos!E9-$C9)/$C9 -> 0 | F9: =(ResultadosObtidos!F9-$C9)/$C9 -> 0.47727273 | G9: =(ResultadosObtidos!G9-$C9)/$C9 -> 0.72727273 | H9: =(ResultadosObtidos!H9-$C9)/$C9 -> 0.5 | I9: =(ResultadosObtidos!I9-$C9)/$C9 -> 0.79545455
B10: =ResultadosObtidos!B10 -> nome instancia 5 | C10: =ResultadosObtidos!C10 -> 33 | D10: =IF(ISBLANK(ResultadosObtidos!D10),"",(ResultadosObtidos!D10-$C10)/$C10) -> 0.03030303 | E10: =(ResultadosObtidos!E10-$C10)/$C10 -> 0.81818182 | F10: =(ResultadosObtidos!F10-$C10)/$C10 -> 0.72727273 | G10: =(ResultadosObtidos!G10-$C10)/$C10 -> 0.81818182 | H10: =(ResultadosObtidos!H10-$C10)/$C10 -> 0 | I10: =(ResultadosObtidos!I10-$C10)/$C10 -> 0.42424242
B11: =ResultadosObtidos!B11 -> nome instancia 6 | C11: =ResultadosObtidos!C11 -> 34 | D11: =IF(ISBLANK(ResultadosObtidos!D11),"",(ResultadosObtidos!D11-$C11)/$C11) -> 0.32352941 | E11: =(ResultadosObtidos!E11-$C11)/$C11 -> 1.2058824 | F11: =(ResultadosObtidos!F11-$C11)/$C11 -> 0.47058824 | G11: =(ResultadosObtidos!G11-$C11)/$C11 -> 1.0882353 | H11: =(ResultadosObtidos!H11-$C11)/$C11 -> 0 | I11: =(ResultadosObtidos!I11-$C11)/$C11 -> 0.55882353
B12: =ResultadosObtidos!B12 -> nome instancia 7 | C12: =ResultadosObtidos!C12 -> 48 | D12: =IF(ISBLANK(ResultadosObtidos!D12),"",(ResultadosObtidos!D12-$C12)/$C12) -> 0.020833333 | E12: =(ResultadosObtidos!E12-$C12)/$C12 -> 0.10416667 | F12: =(ResultadosObtidos!F12-$C12)/$C12 -> 0 | G12: =(ResultadosObtidos!G12-$C12)/$C12 -> 0.3125 | H12: =(ResultadosObtidos!H12-$C12)/$C12 -> 0.20833333 | I12: =(ResultadosObtidos!I12-$C12)/$C12 -> 0.16666667
B13: =ResultadosObtidos!B13 -> nome instancia 8 | C13: =ResultadosObtidos!C13 -> 44 | D13: =IF(ISBLANK(ResultadosObtidos!D13),"",(ResultadosObtidos!D13-$C13)/$C13) -> 0 | E13: =(ResultadosObtidos!E13-$C13)/$C13 -> 0 | F13: =(ResultadosObtidos!F13-$C13)/$C13 -> 0.52272727 | G13: =(ResultadosObtidos!G13-$C13)/$C13 -> 0.59090909 | H13: =(ResultadosObtidos!H13-$C13)/$C13 -> 0.022727273 | I13: =(ResultadosObtidos!I13-$C13)/$C13 -> 0.068181818
B14: =ResultadosObtidos!B14 -> nome instancia 9 | C14: =ResultadosObtidos!C14 -> 35 | D14: =IF(ISBLANK(ResultadosObtidos!D14),"",(ResultadosObtidos!D14-$C14)/$C14) -> 0 | E14: =(ResultadosObtidos!E14-$C14)/$C14 -> 0.17142857 | F14: =(ResultadosObtidos!F14-$C14)/$C14 -> 0.77142857 | G14: =(ResultadosObtidos!G14-$C14)/$C14 -> 0.54285714 | H14: =(ResultadosObtidos!H14-$C14)/$C14 -> 0.057142857 | I14: =(ResultadosObtidos!I14-$C14)/$C14 -> 0
B15: =ResultadosObtidos!B15 -> nome instancia 10 | C15: =ResultadosObtidos!C15 -> 36 | D15: =IF(ISBLANK(ResultadosObtidos!D15),"",(ResultadosObtidos!D15-$C15)/$C15) -> 0.027777778 | E15: =(ResultadosObtidos!E15-$C15)/$C15 -> 0 | F15: =(ResultadosObtidos!F15-$C15)/$C15 -> 1.1388889 | G15: =(ResultadosObtidos!G15-$C15)/$C15 -> 0.41666667 | H15: =(ResultadosObtidos!H15-$C15)/$C15 -> 0.19444444 | I15: =(ResultadosObtidos!I15-$C15)/$C15 -> 0.30555556
B16: =ResultadosObtidos!B16 -> nome instancia 11 | C16: =ResultadosObtidos!C16 -> 38 | D16: =IF(ISBLANK(ResultadosObtidos!D16),"",(ResultadosObtidos!D16-$C16)/$C16) -> 0 | E16: =(ResultadosObtidos!E16-$C16)/$C16 -> 0.21052632 | F16: =(ResultadosObtidos!F16-$C16)/$C16 -> 0.97368421 | G16: =(ResultadosObtidos!G16-$C16)/$C16 -> 0.97368421 | H16: =(ResultadosObtidos!H16-$C16)/$C16 -> 0 | I16: =(ResultadosObtidos!I16-$C16)/$C16 -> 0.26315789
B17: =ResultadosObtidos!B17 -> nome instancia 12 | C17: =ResultadosObtidos!C17 -> 32 | D17: =IF(ISBLANK(ResultadosObtidos!D17),"",(ResultadosObtidos!D17-$C17)/$C17) -> 0.03125 | E17: =(ResultadosObtidos!E17-$C17)/$C17 -> 0.9375 | F17: =(ResultadosObtidos!F17-$C17)/$C17 -> 0.40625 | G17: =(ResultadosObtidos!G17-$C17)/$C17 -> 0 | H17: =(ResultadosObtidos!H17-$C17)/$C17 -> 0.25 | I17: =(ResultadosObtidos!I17-$C17)/$C17 -> 0.65625
B18: =ResultadosObtidos!B18 -> nome instancia 13 | C18: =ResultadosObtidos!C18 -> 38 | D18: =IF(ISBLANK(ResultadosObtidos!D18),"",(ResultadosObtidos!D18-$C18)/$C18) -> 0.026315789 | E18: =(ResultadosObtidos!E18-$C18)/$C18 -> 1 | F18: =(ResultadosObtidos!F18-$C18)/$C18 -> 0 | G18: =(ResultadosObtidos!G18-$C18)/$C18 -> 0.73684211 | H18: =(ResultadosObtidos!H18-$C18)/$C18 -> 0.5 | I18: =(ResultadosObtidos!I18-$C18)/$C18 -> 0.052631579
... B35: =ResultadosObtidos!B35 -> nome instancia 30 | C35: =ResultadosObtidos!C35 -> 35 | D35: =IF(ISBLANK(ResultadosObtidos!D35),"",(ResultadosObtidos!D35-$C35)/$C35) -> 0.028571429 | E35: =(ResultadosObtidos!E35-$C35)/$C35 -> 0.17142857 | F35: =(ResultadosObtidos!F35-$C35)/$C35 -> 0.77142857 | G35: =(ResultadosObtidos!G35-$C35)/$C35 -> 0.54285714 | H35: =(ResultadosObtidos!H35-$C35)/$C35 -> 0.057142857 | I35: =(ResultadosObtidos!I35-$C35)/$C35 -> 0

Sheet Desvio_Latex
B2: INSIRA O NUMERO DE CASAS DECIMAIS QUE DEVERÁ SER UTILIZADO NA IMPRESSÃO DA COLUNA BEST: | C2: 0 | F2: =IF(C2=0,"0",CONCATENATE("0,",REPT(0,C2))) -> 0
B3: INSIRA O NUMERO DE CASAS DECIMAIS QUE DEVERÁ SER UTILIZADO NA IMPRESSÃO DOS PERCENTUAIS: | C3: 1 | F3: =IF(C3=0,"0",CONCATENATE("0.",REPT(0,C3))) -> 0.0
B5: LINHAS DAS MÉDIAS DE CADA ALGORITMO EM LATEX (ÚLTIMA LINHA DA TABELA):
B6: =IF(OR(H6="",I6="",J6="",K6="",L6=""),"LINHA VAZIA OU ERRO EM ALGUMA COLUNA",CONCATENATE(E6," & ",N6,O6,P6,Q6,R6,S6,T6)) -> \textbf{Média} & 100 & \textbf{0,0 \% } & \textbf{0,3 \% } & \textbf{0,6 \% } & \textbf{0,5 \% } & \textbf{0,3 \% } & \textbf{0,2 \% } \\ | E6: \textbf{Média} | F6: =IFERROR(IF(DesvioPercentual!C6<>"",SUBSTITUTE(TEXT(DesvioPercentual!C6,$F$2),".",","),""),"") -> 100 | G6: =IFERROR(IF(DesvioPercentual!N6<>"",SUBSTITUTE(TEXT(DesvioPercentual!N6,$F$3),".",","),""),"") -> 0,0 | H6: =IFERROR(IF(DesvioPercentual!O6<>"",SUBSTITUTE(TEXT(DesvioPercentual!O6,$F$3),".",","),""),"") -> 0,3 | I6: =IFERROR(IF(DesvioPercentual!P6<>"",SUBSTITUTE(TEXT(DesvioPercentual!P6,$F$3),".",","),""),"") -> 0,6 | J6: =IFERROR(IF(DesvioPercentual!Q6<>"",SUBSTITUTE(TEXT(DesvioPercentual!Q6,$F$3),".",","),""),"") -> 0,5 | K6: =IFERROR(IF(DesvioPercentual!R6<>"",SUBSTITUTE(TEXT(DesvioPercentual!R6,$F$3),".",","),""),"") -> 0,3 | L6: =IFERROR(IF(DesvioPercentual!S6<>"",SUBSTITUTE(TEXT(DesvioPercentual!S6,$F$3),".",","),""),"") -> 0,2 | N6: =CONCATENATE(F6," & ") -> 100 & | O6: =IF(G6="","",CONCATENATE("\textbf{",G6," \% ","} & ")) -> \textbf{0,0 \% } & | P6: =IF(H6="","",CONCATENATE("\textbf{",H6," \% ","} & ")) -> \textbf{0,3 \% } & | Q6: =IF(I6="","",CONCATENATE("\textbf{",I6," \% ","} & ")) -> \textbf{0,6 \% } & | R6: =IF(J6="","",CONCATENATE("\textbf{",J6," \% ","} & ")) -> \textbf{0,5 \% } & | S6: =IF(K6="","",CONCATENATE("\textbf{",K6," \% ","} & ")) -> \textbf{0,3 \% } & | T6: =IF(L6="","",CONCATENATE("\textbf{",L6," \% ","} \\ ")) -> \textbf{0,2 \% } \\ | U6: =IF(M6="","",CONCATENATE("\textbf{",M6," \% ","} & "))
B8: LINHAS DAS INSTANCIAS EM LATEX:
B9: =IF(OR(H9="",I9="",J9="",K9="",L9=""),"LINHA VAZIA OU ERRO EM ALGUMA COLUNA",CONCATENATE(E9," & ",N9,O9,P9,Q9,R9,S9,T9)) -> nome instancia 1 & 100 & 0,0 \% & \textbf{0,0 \% } & 0,1 \% & 0,2 \% & 0,3 \% & 0,4 \% \\ | E9: =DesvioPercentual!B6 -> nome instancia 1 | F9: =IFERROR(IF(DesvioPercentual!C6<>"",SUBSTITUTE(TEXT(DesvioPercentual!C6,$F$2),".",","),""),"") -> 100 | G9: =IFERROR(IF(DesvioPercentual!D6<>"",SUBSTITUTE(TEXT(DesvioPercentual!D6,$F$3),".",","),""),"") -> 0,0 | H9: =IFERROR(IF(DesvioPercentual!E6<>"",SUBSTITUTE(TEXT(DesvioPercentual!E6,$F$3),".",","),""),"") -> 0,0 | I9: =IFERROR(IF(DesvioPercentual!F6<>"",SUBSTITUTE(TEXT(DesvioPercentual!F6,$F$3),".",","),""),"") -> 0,1 | J9: =IFERROR(IF(DesvioPercentual!G6<>"",SUBSTITUTE(TEXT(DesvioPercentual!G6,$F$3),".",","),""),"") -> 0,2 | K9: =IFERROR(IF(DesvioPercentual!H6<>"",SUBSTITUTE(TEXT(DesvioPercentual!H6,$F$3),".",","),""),"") -> 0,3 | L9: =IFERROR(IF(DesvioPercentual!I6<>"",SUBSTITUTE(TEXT(DesvioPercentual!I6,$F$3),".",","),""),"") -> 0,4 | N9: =CONCATENATE(F9," & ") -> 100 & | O9: =IF(G9="","",CONCATENATE(IF(ResultadosObtidos!D6=ResultadosObtidos!$C6,"\textbf{",""),G9," \% ",IF(ResultadosObtidos!D6=ResultadosObtidos!$C6,"} & "," & "))) -> 0,0 \% & | P9: =IF(H9="","",CONCATENATE(IF(ResultadosObtidos!E6=ResultadosObtidos!$C6,"\textbf{",""),H9," \% ",IF(ResultadosObtidos!E6=ResultadosObtidos!$C6,"} & "," & "))) -> \textbf{0,0 \% } & | Q9: =IF(I9="","",CONCATENATE(IF(ResultadosObtidos!F6=ResultadosObtidos!$C6,"\textbf{",""),I9," \% ",IF(ResultadosObtidos!F6=ResultadosObtidos!$C6,"} & "," & "))) -> 0,1 \% & | R9: =IF(J9="","",CONCATENATE(IF(ResultadosObtidos!G6=ResultadosObtidos!$C6,"\textbf{",""),J9," \% ",IF(ResultadosObtidos!G6=ResultadosObtidos!$C6,"} & "," & "))) -> 0,2 \% & | S9: =IF(K9="","",CONCATENATE(IF(ResultadosObtidos!H6=ResultadosObtidos!$C6,"\textbf{",""),K9," \% ",IF(ResultadosObtidos!H6=ResultadosObtidos!$C6,"} & "," & "))) -> 0,3 \% & | T9: =IF(L9="","",CONCATENATE(IF(ResultadosObtidos!I6=ResultadosObtidos!$C6,"\textbf{",""),L9," \% ",IF(ResultadosObtidos!I6=ResultadosObtidos!$C6,"} \\ "," \\ "))) -> 0,4 \% \\
B10: =IF(OR(H10="",I10="",J10="",K10="",L10=""),"LINHA VAZIA OU ERRO EM ALGUMA COLUNA",CONCATENATE(E10," & ",N10,O10,P10,Q10,R10,S10,T10)) -> nome instancia 2 & 36 & 0,0 \% & \textbf{0,0 \% } & 1,0 \% & 0,7 \% & 1,2 \% & 0,9 \% \\ | E10: =ResultadosObtidos!B7 -> nome instancia 2 | F10: =IFERROR(IF(DesvioPercentual!C7<>"",SUBSTITUTE(TEXT(DesvioPercentual!C7,$F$2),".",","),""),"") -> 36 | G10: =IFERROR(IF(DesvioPercentual!D7<>"",SUBSTITUTE(TEXT(DesvioPercentual!D7,$F$3),".",","),""),"") -> 0,0 | H10: =IFERROR(IF(DesvioPercentual!E7<>"",SUBSTITUTE(TEXT(DesvioPercentual!E7,$F$3),".",","),""),"") -> 0,0 | I10: =IFERROR(IF(DesvioPercentual!F7<>"",SUBSTITUTE(TEXT(DesvioPercentual!F7,$F$3),".",","),""),"") -> 1,0 | J10: =IFERROR(IF(DesvioPercentual!G7<>"",SUBSTITUTE(TEXT(DesvioPercentual!G7,$F$3),".",","),""),"") -> 0,7 | K10: =IFERROR(IF(DesvioPercentual!H7<>"",SUBSTITUTE(TEXT(DesvioPercentual!H7,$F$3),".",","),""),"") -> 1,2 | L10: =IFERROR(IF(DesvioPercentual!I7<>"",SUBSTITUTE(TEXT(DesvioPercentual!I7,$F$3),".",","),""),"") -> 0,9 | N10: =CONCATENATE(F10," & ") -> 36 & | O10: =IF(G10="","",CONCATENATE(IF(ResultadosObtidos!D7=ResultadosObtidos!$C7,"\textbf{",""),G10," \% ",IF(ResultadosObtidos!D7=ResultadosObtidos!$C7,"} & "," & "))) -> 0,0 \% & | P10: =IF(H10="","",CONCATENATE(IF(ResultadosObtidos!E7=ResultadosObtidos!$C7,"\textbf{",""),H10," \% ",IF(ResultadosObtidos!E7=ResultadosObtidos!$C7,"} & "," & "))) -> \textbf{0,0 \% } & | Q10: =IF(I10="","",CONCATENATE(IF(ResultadosObtidos!F7=ResultadosObtidos!$C7,"\textbf{",""),I10," \% ",IF(ResultadosObtidos!F7=ResultadosObtidos!$C7,"} & "," & "))) -> 1,0 \% & | R10: =IF(J10="","",CONCATENATE(IF(ResultadosObtidos!G7=ResultadosObtidos!$C7,"\textbf{",""),J10," \% ",IF(ResultadosObtidos!G7=ResultadosObtidos!$C7,"} & "," & "))) -> 0,7 \% & | S10: =IF(K10="","",CONCATENATE(IF(ResultadosObtidos!H7=ResultadosObtidos!$C7,"\textbf{",""),K10," \% ",IF(ResultadosObtidos!H7=ResultadosObtidos!$C7,"} & "," & "))) -> 1,2 \% & | T10: =IF(L10="","",CONCATENATE(IF(ResultadosObtidos!I7=ResultadosObtidos!$C7,"\textbf{",""),L10," \% ",IF(ResultadosObtidos!I7=ResultadosObtidos!$C7,"} \\ "," \\ "))) -> 0,9 \% \\
B11: =IF(OR(H11="",I11="",J11="",K11="",L11=""),"LINHA VAZIA OU ERRO EM ALGUMA COLUNA",CONCATENATE(E11," & ",N11,O11,P11,Q11,R11,S11,T11)) -> nome instancia 3 & 30 & 0,1 \% & 1,6 \% & 0,8 \% & \textbf{0,0 \% } & 1,6 \% & 1,5 \% \\ | E11: =ResultadosObtidos!B8 -> nome instancia 3 | F11: =IFERROR(IF(DesvioPercentual!C8<>"",SUBSTITUTE(TEXT(DesvioPercentual!C8,$F$2),".",","),""),"") -> 30 | G11: =IFERROR(IF(DesvioPercentual!D8<>"",SUBSTITUTE(TEXT(DesvioPercentual!D8,$F$3),".",","),""),"") -> 0,1 | H11: =IFERROR(IF(DesvioPercentual!E8<>"",SUBSTITUTE(TEXT(DesvioPercentual!E8,$F$3),".",","),""),"") -> 1,6 | I11: =IFERROR(IF(DesvioPercentual!F8<>"",SUBSTITUTE(TEXT(DesvioPercentual!F8,$F$3),".",","),""),"") -> 0,8 | J11: =IFERROR(IF(DesvioPercentual!G8<>"",SUBSTITUTE(TEXT(DesvioPercentual!G8,$F$3),".",","),""),"") -> 0,0 | K11: =IFERROR(IF(DesvioPercentual!H8<>"",SUBSTITUTE(TEXT(DesvioPercentual!H8,$F$3),".",","),""),"") -> 1,6 | L11: =IFERROR(IF(DesvioPercentual!I8<>"",SUBSTITUTE(TEXT(DesvioPercentual!I8,$F$3),".",","),""),"") -> 1,5 | N11: =CONCATENATE(F11," & ") -> 30 & | O11: =IF(G11="","",CONCATENATE(IF(ResultadosObtidos!D8=ResultadosObtidos!$C8,"\textbf{",""),G11," \% ",IF(ResultadosObtidos!D8=ResultadosObtidos!$C8,"} & "," & "))) -> 0,1 \% & | P11: =IF(H11="","",CONCATENATE(IF(ResultadosObtidos!E8=ResultadosObtidos!$C8,"\textbf{",""),H11," \% ",IF(ResultadosObtidos!E8=ResultadosObtidos!$C8,"} & "," & "))) -> 1,6 \% & | Q11: =IF(I11="","",CONCATENATE(IF(ResultadosObtidos!F8=ResultadosObtidos!$C8,"\textbf{",""),I11," \% ",IF(ResultadosObtidos!F8=ResultadosObtidos!$C8,"} & "," & "))) -> 0,8 \% & | R11: =IF(J11="","",CONCATENATE(IF(ResultadosObtidos!G8=ResultadosObtidos!$C8,"\textbf{",""),J11," \% ",IF(ResultadosObtidos!G8=ResultadosObtidos!$C8,"} & "," & "))) -> \textbf{0,0 \% } & | S11: =IF(K11="","",CONCATENATE(IF(ResultadosObtidos!H8=ResultadosObtidos!$C8,"\textbf{",""),K11," \% ",IF(ResultadosObtidos!H8=ResultadosObtidos!$C8,"} & "," & "))) -> 1,6 \% & | T11: =IF(L11="","",CONCATENATE(IF(ResultadosObtidos!I8=ResultadosObtidos!$C8,"\textbf{",""),L11," \% ",IF(ResultadosObtidos!I8=ResultadosObtidos!$C8,"} \\ "," \\ "))) -> 1,5 \% \\
B12: =IF(OR(H12="",I12="",J12="",K12="",L12=""),"LINHA VAZIA OU ERRO EM ALGUMA COLUNA",CONCATENATE(E12," & ",N12,O12,P12,Q12,R12,S12,T12)) -> nome instancia 4 & 44 & \textbf{0,0 \% } & \textbf{0,0 \% } & 0,5 \% & 0,7 \% & 0,5 \% & 0,8 \% \\ | E12: =ResultadosObtidos!B9 -> nome instancia 4 | F12: =IFERROR(IF(DesvioPercentual!C9<>"",SUBSTITUTE(TEXT(DesvioPercentual!C9,$F$2),".",","),""),"") -> 44 | G12: =IFERROR(IF(DesvioPercentual!D9<>"",SUBSTITUTE(TEXT(DesvioPercentual!D9,$F$3),".",","),""),"") -> 0,0 | H12: =IFERROR(IF(DesvioPercentual!E9<>"",SUBSTITUTE(TEXT(DesvioPercentual!E9,$F$3),".",","),""),"") -> 0,0 | I12: =IFERROR(IF(DesvioPercentual!F9<>"",SUBSTITUTE(TEXT(DesvioPercentual!F9,$F$3),".",","),""),"") -> 0,5 | J12: =IFERROR(IF(DesvioPercentual!G9<>"",SUBSTITUTE(TEXT(DesvioPercentual!G9,$F$3),".",","),""),"") -> 0,7 | K12: =IFERROR(IF(DesvioPercentual!H9<>"",SUBSTITUTE(TEXT(DesvioPercentual!H9,$F$3),".",","),""),"") -> 0,5 | L12: =IFERROR(IF(DesvioPercentual!I9<>"",SUBSTITUTE(TEXT(DesvioPercentual!I9,$F$3),".",","),""),"") -> 0,8 | N12: =CONCATENATE(F12," & ") -> 44 & | O12: =IF(G12="","",CONCATENATE(IF(ResultadosObtidos!D9=ResultadosObtidos!$C9,"\textbf{",""),G12," \% ",IF(ResultadosObtidos!D9=ResultadosObtidos!$C9,"} & "," & "))) -> \textbf{0,0 \% } & | P12: =IF(H12="","",CONCATENATE(IF(ResultadosObtidos!E9=ResultadosObtidos!$C9,"\textbf{",""),H12," \% ",IF(ResultadosObtidos!E9=ResultadosObtidos!$C9,"} & "," & "))) -> \textbf{0,0 \% } & | Q12: =IF(I12="","",CONCATENATE(IF(ResultadosObtidos!F9=ResultadosObtidos!$C9,"\textbf{",""),I12," \% ",IF(ResultadosObtidos!F9=ResultadosObtidos!$C9,"} & "," & "))) -> 0,5 \% & | R12: =IF(J12="","",CONCATENATE(IF(ResultadosObtidos!G9=ResultadosObtidos!$C9,"\textbf{",""),J12," \% ",IF(ResultadosObtidos!G9=ResultadosObtidos!$C9,"} & "," & "))) -> 0,7 \% & | S12: =IF(K12="","",CONCATENATE(IF(ResultadosObtidos!H9=ResultadosObtidos!$C9,"\textbf{",""),K12," \% ",IF(ResultadosObtidos!H9=ResultadosObtidos!$C9,"} & "," & "))) -> 0,5 \% & | T12: =IF(L12="","",CONCATENATE(IF(ResultadosObtidos!I9=ResultadosObtidos!$C9,"\textbf{",""),L12," \% ",IF(ResultadosObtidos!I9=ResultadosObtidos!$C9,"} \\ "," \\ "))) -> 0,8 \% \\
B13: =IF(OR(H13="",I13="",J13="",K13="",L13=""),"LINHA VAZIA OU ERRO EM ALGUMA COLUNA",CONCATENATE(E13," & ",N13,O13,P13,Q13,R13,S13,T13)) -> nome instancia 5 & 33 & 0,0 \% & 0,8 \% & 0,7 \% & 0,8 \% & \textbf{0,0 \% } & 0,4 \% \\ | E13: =ResultadosObtidos!B10 -> nome instancia 5 | F13: =IFERROR(IF(DesvioPercentual!C10<>"",SUBSTITUTE(TEXT(DesvioPercentual!C10,$F$2),".",","),""),"") -> 33 | G13: =IFERROR(IF(DesvioPercentual!D10<>"",SUBSTITUTE(TEXT(DesvioPercentual!D10,$F$3),".",","),""),"") -> 0,0 | H13: =IFERROR(IF(DesvioPercentual!E10<>"",SUBSTITUTE(TEXT(DesvioPercentual!E10,$F$3),".",","),""),"") -> 0,8 | I13: =IFERROR(IF(DesvioPercentual!F10<>"",SUBSTITUTE(TEXT(DesvioPercentual!F10,$F$3),".",","),""),"") -> 0,7 | J13: =IFERROR(IF(DesvioPercentual!G10<>"",SUBSTITUTE(TEXT(DesvioPercentual!G10,$F$3),".",","),""),"") -> 0,8 | K13: =IFERROR(IF(DesvioPercentual!H10<>"",SUBSTITUTE(TEXT(DesvioPercentual!H10,$F$3),".",","),""),"") -> 0,0 | L13: =IFERROR(IF(DesvioPercentual!I10<>"",SUBSTITUTE(TEXT(DesvioPercentual!I10,$F$3),".",","),""),"") -> 0,4 | N13: =CONCATENATE(F13," & ") -> 33 & | O13: =IF(G13="","",CONCATENATE(IF(ResultadosObtidos!D10=ResultadosObtidos!$C10,"\textbf{",""),G13," \% ",IF(ResultadosObtidos!D10=ResultadosObtidos!$C10,"} & "," & "))) -> 0,0 \% & | P13: =IF(H13="","",CONCATENATE(IF(ResultadosObtidos!E10=ResultadosObtidos!$C10,"\textbf{",""),H13," \% ",IF(ResultadosObtidos!E10=ResultadosObtidos!$C10,"} & "," & "))) -> 0,8 \% & | Q13: =IF(I13="","",CONCATENATE(IF(ResultadosObtidos!F10=ResultadosObtidos!$C10,"\textbf{",""),I13," \% ",IF(ResultadosObtidos!F10=ResultadosObtidos!$C10,"} & "," & "))) -> 0,7 \% & | R13: =IF(J13="","",CONCATENATE(IF(ResultadosObtidos!G10=ResultadosObtidos!$C10,"\textbf{",""),J13," \% ",IF(ResultadosObtidos!G10=ResultadosObtidos!$C10,"} & "," & "))) -> 0,8 \% & | S13: =IF(K13="","",CONCATENATE(IF(ResultadosObtidos!H10=ResultadosObtidos!$C10,"\textbf{",""),K13," \% ",IF(ResultadosObtidos!H10=ResultadosObtidos!$C10,"} & "," & "))) -> \textbf{0,0 \% } & | T13: =IF(L13="","",CONCATENATE(IF(ResultadosObtidos!I10=ResultadosObtidos!$C10,"\textbf{",""),L13," \% ",IF(ResultadosObtidos!I10=ResultadosObtidos!$C10,"} \\ "," \\ "))) -> 0,4 \% \\
B14: =IF(OR(H14="",I14="",J14="",K14="",L14=""),"LINHA VAZIA OU ERRO EM ALGUMA COLUNA",CONCATENATE(E14," & ",N14,O14,P14,Q14,R14,S14,T14)) -> nome instancia 6 & 34 & 0,3 \% & 1,2 \% & 0,5 \% & 1,1 \% & \textbf{0,0 \% } & 0,6 \% \\ | E14: =ResultadosObtidos!B11 -> nome instancia 6 | F14: =IFERROR(IF(DesvioPercentual!C11<>"",SUBSTITUTE(TEXT(DesvioPercentual!C11,$F$2),".",","),""),"") -> 34 | G14: =IFERROR(IF(DesvioPercentual!D11<>"",SUBSTITUTE(TEXT(DesvioPercentual!D11,$F$3),".",","),""),"") -> 0,3 | H14: =IFERROR(IF(DesvioPercentual!E11<>"",SUBSTITUTE(TEXT(DesvioPercentual!E11,$F$3),".",","),""),"") -> 1,2 | I14: =IFERROR(IF(DesvioPercentual!F11<>"",SUBSTITUTE(TEXT(DesvioPercentual!F11,$F$3),".",","),""),"") -> 0,5 | J14: =IFERROR(IF(DesvioPercentual!G11<>"",SUBSTITUTE(TEXT(DesvioPercentual!G11,$F$3),".",","),""),"") -> 1,1 | K14: =IFERROR(IF(DesvioPercentual!H11<>"",SUBSTITUTE(TEXT(DesvioPercentual!H11,$F$3),".",","),""),"") -> 0,0 | L14: =IFERROR(IF(DesvioPercentual!I11<>"",SUBSTITUTE(TEXT(DesvioPercentual!I11,$F$3),".",","),""),"") -> 0,6 | N14: =CONCATENATE(F14," & ") -> 34 & | O14: =IF(G14="","",CONCATENATE(IF(ResultadosObtidos!D11=ResultadosObtidos!$C11,"\textbf{",""),G14," \% ",IF(ResultadosObtidos!D11=ResultadosObtidos!$C11,"} & "," & "))) -> 0,3 \% & | P14: =IF(H14="","",CONCATENATE(IF(ResultadosObtidos!E11=ResultadosObtidos!$C11,"\textbf{",""),H14," \% ",IF(ResultadosObtidos!E11=ResultadosObtidos!$C11,"} & "," & "))) -> 1,2 \% & | Q14: =IF(I14="","",CONCATENATE(IF(ResultadosObtidos!F11=ResultadosObtidos!$C11,"\textbf{",""),I14," \% ",IF(ResultadosObtidos!F11=ResultadosObtidos!$C11,"} & "," & "))) -> 0,5 \% & | R14: =IF(J14="","",CONCATENATE(IF(ResultadosObtidos!G11=ResultadosObtidos!$C11,"\textbf{",""),J14," \% ",IF(ResultadosObtidos!G11=ResultadosObtidos!$C11,"} & "," & "))) -> 1,1 \% & | S14: =IF(K14="","",CONCATENATE(IF(ResultadosObtidos!H11=ResultadosObtidos!$C11,"\textbf{",""),K14," \% ",IF(ResultadosObtidos!H11=ResultadosObtidos!$C11,"} & "," & "))) -> \textbf{0,0 \% } & | T14: =IF(L14="","",CONCATENATE(IF(ResultadosObtidos!I11=ResultadosObtidos!$C11,"\textbf{",""),L14," \% ",IF(ResultadosObtidos!I11=ResultadosObtidos!$C11,"} \\ "," \\ "))) -> 0,6 \% \\
B15: =IF(OR(H15="",I15="",J15="",K15="",L15=""),"LINHA VAZIA OU ERRO EM ALGUMA COLUNA",CONCATENATE(E15," & ",N15,O15,P15,Q15,R15,S15,T15)) -> nome instancia 7 & 48 & 0,0 \% & 0,1 \% & \textbf{0,0 \% } & 0,3 \% & 0,2 \% & 0,2 \% \\ | E15: =ResultadosObtidos!B12 -> nome instancia 7 | F15: =IFERROR(IF(DesvioPercentual!C12<>"",SUBSTITUTE(TEXT(DesvioPercentual!C12,$F$2),".",","),""),"") -> 48 | G15: =IFERROR(IF(DesvioPercentual!D12<>"",SUBSTITUTE(TEXT(DesvioPercentual!D12,$F$3),".",","),""),"") -> 0,0 | H15: =IFERROR(IF(DesvioPercentual!E12<>"",SUBSTITUTE(TEXT(DesvioPercentual!E12,$F$3),".",","),""),"") -> 0,1 | I15: =IFERROR(IF(DesvioPercentual!F12<>"",SUBSTITUTE(TEXT(DesvioPercentual!F12,$F$3),".",","),""),"") -> 0,0 | J15: =IFERROR(IF(DesvioPercentual!G12<>"",SUBSTITUTE(TEXT(DesvioPercentual!G12,$F$3),".",","),""),"") -> 0,3 | K15: =IFERROR(IF(DesvioPercentual!H12<>"",SUBSTITUTE(TEXT(DesvioPercentual!H12,$F$3),".",","),""),"") -> 0,2 | L15: =IFERROR(IF(DesvioPercentual!I12<>"",SUBSTITUTE(TEXT(DesvioPercentual!I12,$F$3),".",","),""),"") -> 0,2 | N15: =CONCATENATE(F15," & ") -> 48 & | O15: =IF(G15="","",CONCATENATE(IF(ResultadosObtidos!D12=ResultadosObtidos!$C12,"\textbf{",""),G15," \% ",IF(ResultadosObtidos!D12=ResultadosObtidos!$C12,"} & "," & "))) -> 0,0 \% & | P15: =IF(H15="","",CONCATENATE(IF(ResultadosObtidos!E12=ResultadosObtidos!$C12,"\textbf{",""),H15," \% ",IF(ResultadosObtidos!E12=ResultadosObtidos!$C12,"} & "," & "))) -> 0,1 \% & | Q15: =IF(I15="","",CONCATENATE(IF(ResultadosObtidos!F12=ResultadosObtidos!$C12,"\textbf{",""),I15," \% ",IF(ResultadosObtidos!F12=ResultadosObtidos!$C12,"} & "," & "))) -> \textbf{0,0 \% } & | R15: =IF(J15="","",CONCATENATE(IF(ResultadosObtidos!G12=ResultadosObtidos!$C12,"\textbf{",""),J15," \% ",IF(ResultadosObtidos!G12=ResultadosObtidos!$C12,"} & "," & "))) -> 0,3 \% & | S15: =IF(K15="","",CONCATENATE(IF(ResultadosObtidos!H12=ResultadosObtidos!$C12,"\textbf{",""),K15," \% ",IF(ResultadosObtidos!H12=ResultadosObtidos!$C12,"} & "," & "))) -> 0,2 \% & | T15: =IF(L15="","",CONCATENATE(IF(ResultadosObtidos!I12=ResultadosObtidos!$C12,"\textbf{",""),L15," \% ",IF(ResultadosObtidos!I12=ResultadosObtidos!$C12,"} \\ "," \\ "))) -> 0,2 \% \\
B16: =IF(OR(H16="",I16="",J16="",K16="",L16=""),"LINHA VAZIA OU ERRO EM ALGUMA COLUNA",CONCATENATE(E16," & ",N16,O16,P16,Q16,R16,S16,T16)) -> nome instancia 8 & 44 & \textbf{0,0 \% } & \textbf{0,0 \% } & 0,5 \% & 0,6 \% & 0,0 \% & 0,1 \% \\ | E16: =ResultadosObtidos!B13 -> nome instancia 8 | F16: =IFERROR(IF(DesvioPercentual!C13<>"",SUBSTITUTE(TEXT(DesvioPercentual!C13,$F$2),".",","),""),"") -> 44 | G16: =IFERROR(IF(DesvioPercentual!D13<>"",SUBSTITUTE(TEXT(DesvioPercentual!D13,$F$3),".",","),""),"") -> 0,0 | H16: =IFERROR(IF(DesvioPercentual!E13<>"",SUBSTITUTE(TEXT(DesvioPercentual!E13,$F$3),".",","),""),"") -> 0,0 | I16: =IFERROR(IF(DesvioPercentual!F13<>"",SUBSTITUTE(TEXT(DesvioPercentual!F13,$F$3),".",","),""),"") -> 0,5 | J16: =IFERROR(IF(DesvioPercentual!G13<>"",SUBSTITUTE(TEXT(DesvioPercentual!G13,$F$3),".",","),""),"") -> 0,6 | K16: =IFERROR(IF(DesvioPercentual!H13<>"",SUBSTITUTE(TEXT(DesvioPercentual!H13,$F$3),".",","),""),"") -> 0,0 | L16: =IFERROR(IF(DesvioPercentual!I13<>"",SUBSTITUTE(TEXT(DesvioPercentual!I13,$F$3),".",","),""),"") -> 0,1 | N16: =CONCATENATE(F16," & ") -> 44 & | O16: =IF(G16="","",CONCATENATE(IF(ResultadosObtidos!D13=ResultadosObtidos!$C13,"\textbf{",""),G16," \% ",IF(ResultadosObtidos!D13=ResultadosObtidos!$C13,"} & "," & "))) -> \textbf{0,0 \% } & | P16: =IF(H16="","",CONCATENATE(IF(ResultadosObtidos!E13=ResultadosObtidos!$C13,"\textbf{",""),H16," \% ",IF(ResultadosObtidos!E13=ResultadosObtidos!$C13,"} & "," & "))) -> \textbf{0,0 \% } & | Q16: =IF(I16="","",CONCATENATE(IF(ResultadosObtidos!F13=ResultadosObtidos!$C13,"\textbf{",""),I16," \% ",IF(ResultadosObtidos!F13=ResultadosObtidos!$C13,"} & "," & "))) -> 0,5 \% & | R16: =IF(J16="","",CONCATENATE(IF(ResultadosObtidos!G13=ResultadosObtidos!$C13,"\textbf{",""),J16," \% ",IF(ResultadosObtidos!G13=ResultadosObtidos!$C13,"} & "," & "))) -> 0,6 \% & | S16: =IF(K16="","",CONCATENATE(IF(ResultadosObtidos!H13=ResultadosObtidos!$C13,"\textbf{",""),K16," \% ",IF(ResultadosObtidos!H13=ResultadosObtidos!$C13,"} & "," & "))) -> 0,0 \% & | T16: =IF(L16="","",CONCATENATE(IF(ResultadosObtidos!I13=ResultadosObtidos!$C13,"\textbf{",""),L16," \% ",IF(ResultadosObtidos!I13=ResultadosObtidos!$C13,"} \\ "," \\ "))) -> 0,1 \% \\
B17: =IF(OR(H17="",I17="",J17="",K17="",L17=""),"LINHA VAZIA OU ERRO EM ALGUMA COLUNA",CONCATENATE(E17," & ",N17,O17,P17,Q17,R17,S17,T17)) -> nome instancia 9 & 35 & \textbf{0,0 \% } & 0,2 \% & 0,8 \% & 0,5 \% & 0,1 \% & \textbf{0,0 \% } \\ | E17: =ResultadosObtidos!B14 -> nome instancia 9 | F17: =IFERROR(IF(DesvioPercentual!C14<>"",SUBSTITUTE(TEXT(DesvioPercentual!C14,$F$2),".",","),""),"") -> 35 | G17: =IFERROR(IF(DesvioPercentual!D14<>"",SUBSTITUTE(TEXT(DesvioPercentual!D14,$F$3),".",","),""),"") -> 0,0 | H17: =IFERROR(IF(DesvioPercentual!E14<>"",SUBSTITUTE(TEXT(DesvioPercentual!E14,$F$3),".",","),""),"") -> 0,2 | I17: =IFERROR(IF(DesvioPercentual!F14<>"",SUBSTITUTE(TEXT(DesvioPercentual!F14,$F$3),".",","),""),"") -> 0,8 | J17: =IFERROR(IF(DesvioPercentual!G14<>"",SUBSTITUTE(TEXT(DesvioPercentual!G14,$F$3),".",","),""),"") -> 0,5 | K17: =IFERROR(IF(DesvioPercentual!H14<>"",SUBSTITUTE(TEXT(DesvioPercentual!H14,$F$3),".",","),""),"") -> 0,1 | L17: =IFERROR(IF(DesvioPercentual!I14<>"",SUBSTITUTE(TEXT(DesvioPercentual!I14,$F$3),".",","),""),"") -> 0,0 | N17: =CONCATENATE(F17," & ") -> 35 & | O17: =IF(G17="","",CONCATENATE(IF(ResultadosObtidos!D14=ResultadosObtidos!$C14,"\textbf{",""),G17," \% ",IF(ResultadosObtidos!D14=ResultadosObtidos!$C14,"} & "," & "))) -> \textbf{0,0 \% } & | P17: =IF(H17="","",CONCATENATE(IF(ResultadosObtidos!E14=ResultadosObtidos!$C14,"\textbf{",""),H17," \% ",IF(ResultadosObtidos!E14=ResultadosObtidos!$C14,"} & "," & "))) -> 0,2 \% & | Q17: =IF(I17="","",CONCATENATE(IF(ResultadosObtidos!F14=ResultadosObtidos!$C14,"\textbf{",""),I17," \% ",IF(ResultadosObtidos!F14=ResultadosObtidos!$C14,"} & "," & "))) -> 0,8 \% & | R17: =IF(J17="","",CONCATENATE(IF(ResultadosObtidos!G14=ResultadosObtidos!$C14,"\textbf{",""),J17," \% ",IF(ResultadosObtidos!G14=ResultadosObtidos!$C14,"} & "," & "))) -> 0,5 \% & | S17: =IF(K17="","",CONCATENATE(IF(ResultadosObtidos!H14=ResultadosObtidos!$C14,"\textbf{",""),K17," \% ",IF(ResultadosObtidos!H14=ResultadosObtidos!$C14,"} & "," & "))) -> 0,1 \% & | T17: =IF(L17="","",CONCATENATE(IF(ResultadosObtidos!I14=ResultadosObtidos!$C14,"\textbf{",""),L17," \% ",IF(ResultadosObtidos!I14=ResultadosObtidos!$C14,"} \\ "," \\ "))) -> \textbf{0,0 \% } \\
B18: =IF(OR(H18="",I18="",J18="",K18="",L18=""),"LINHA VAZIA OU ERRO EM ALGUMA COLUNA",CONCATENATE(E18," & ",N18,O18,P18,Q18,R18,S18,T18)) -> nome instancia 10 & 36 & 0,0 \% & \textbf{0,0 \% } & 1,1 \% & 0,4 \% & 0,2 \% & 0,3 \% \\ | E18: =ResultadosObtidos!B15 -> nome instancia 10 | F18: =IFERROR(IF(DesvioPercentual!C15<>"",SUBSTITUTE(TEXT(DesvioPercentual!C15,$F$2),".",","),""),"") -> 36 | G18: =IFERROR(IF(DesvioPercentual!D15<>"",SUBSTITUTE(TEXT(DesvioPercentual!D15,$F$3),".",","),""),"") -> 0,0 | H18: =IFERROR(IF(DesvioPercentual!E15<>"",SUBSTITUTE(TEXT(DesvioPercentual!E15,$F$3),".",","),""),"") -> 0,0 | I18: =IFERROR(IF(DesvioPercentual!F15<>"",SUBSTITUTE(TEXT(DesvioPercentual!F15,$F$3),".",","),""),"") -> 1,1 | J18: =IFERROR(IF(DesvioPercentual!G15<>"",SUBSTITUTE(TEXT(DesvioPercentual!G15,$F$3),".",","),""),"") -> 0,4 | K18: =IFERROR(IF(DesvioPercentual!H15<>"",SUBSTITUTE(TEXT(DesvioPercentual!H15,$F$3),".",","),""),"") -> 0,2 | L18: =IFERROR(IF(DesvioPercentual!I15<>"",SUBSTITUTE(TEXT(DesvioPercentual!I15,$F$3),".",","),""),"") -> 0,3 | N18: =CONCATENATE(F18," & ") -> 36 & | O18: =IF(G18="","",CONCATENATE(IF(ResultadosObtidos!D15=ResultadosObtidos!$C15,"\textbf{",""),G18," \% ",IF(ResultadosObtidos!D15=ResultadosObtidos!$C15,"} & "," & "))) -> 0,0 \% & | P18: =IF(H18="","",CONCATENATE(IF(ResultadosObtidos!E15=ResultadosObtidos!$C15,"\textbf{",""),H18," \% ",IF(ResultadosObtidos!E15=ResultadosObtidos!$C15,"} & "," & "))) -> \textbf{0,0 \% } & | Q18: =IF(I18="","",CONCATENATE(IF(ResultadosObtidos!F15=ResultadosObtidos!$C15,"\textbf{",""),I18," \% ",IF(ResultadosObtidos!F15=ResultadosObtidos!$C15,"} & "," & "))) -> 1,1 \% & | R18: =IF(J18="","",CONCATENATE(IF(ResultadosObtidos!G15=ResultadosObtidos!$C15,"\textbf{",""),J18," \% ",IF(ResultadosObtidos!G15=ResultadosObtidos!$C15,"} & "," & "))) -> 0,4 \% & | S18: =IF(K18="","",CONCATENATE(IF(ResultadosObtidos!H15=ResultadosObtidos!$C15,"\textbf{",""),K18," \% ",IF(ResultadosObtidos!H15=ResultadosObtidos!$C15,"} & "," & "))) -> 0,2 \% & | T18: =IF(L18="","",CONCATENATE(IF(ResultadosObtidos!I15=ResultadosObtidos!$C15,"\textbf{",""),L18," \% ",IF(ResultadosObtidos!I15=ResultadosObtidos!$C15,"} \\ "," \\ "))) -> 0,3 \% \\
B19: =IF(OR(H19="",I19="",J19="",K19="",L19=""),"LINHA VAZIA OU ERRO EM ALGUMA COLUNA",CONCATENATE(E19," & ",N19,O19,P19,Q19,R19,S19,T19)) -> nome instancia 11 & 38 & \textbf{0,0 \% } & 0,2 \% & 1,0 \% & 1,0 \% & \textbf{0,0 \% } & 0,3 \% \\ | E19: =ResultadosObtidos!B16 -> nome instancia 11 | F19: =IFERROR(IF(DesvioPercentual!C16<>"",SUBSTITUTE(TEXT(DesvioPercentual!C16,$F$2),".",","),""),"") -> 38 | G19: =IFERROR(IF(DesvioPercentual!D16<>"",SUBSTITUTE(TEXT(DesvioPercentual!D16,$F$3),".",","),""),"") -> 0,0 | H19: =IFERROR(IF(DesvioPercentual!E16<>"",SUBSTITUTE(TEXT(DesvioPercentual!E16,$F$3),".",","),""),"") -> 0,2 | I19: =IFERROR(IF(DesvioPercentual!F16<>"",SUBSTITUTE(TEXT(DesvioPercentual!F16,$F$3),".",","),""),"") -> 1,0 | J19: =IFERROR(IF(DesvioPercentual!G16<>"",SUBSTITUTE(TEXT(DesvioPercentual!G16,$F$3),".",","),""),"") -> 1,0 | K19: =IFERROR(IF(DesvioPercentual!H16<>"",SUBSTITUTE(TEXT(DesvioPercentual!H16,$F$3),".",","),""),"") -> 0,0 | L19: =IFERROR(IF(DesvioPercentual!I16<>"",SUBSTITUTE(TEXT(DesvioPercentual!I16,$F$3),".",","),""),"") -> 0,3 | N19: =CONCATENATE(F19," & ") -> 38 & | O19: =IF(G19="","",CONCATENATE(IF(ResultadosObtidos!D16=ResultadosObtidos!$C16,"\textbf{",""),G19," \% ",IF(ResultadosObtidos!D16=ResultadosObtidos!$C16,"} & "," & "))) -> \textbf{0,0 \% } & | P19: =IF(H19="","",CONCATENATE(IF(ResultadosObtidos!E16=ResultadosObtidos!$C16,"\textbf{",""),H19," \% ",IF(ResultadosObtidos!E16=ResultadosObtidos!$C16,"} & "," & "))) -> 0,2 \% & | Q19: =IF(I19="","",CONCATENATE(IF(ResultadosObtidos!F16=ResultadosObtidos!$C16,"\textbf{",""),I19," \% ",IF(ResultadosObtidos!F16=ResultadosObtidos!$C16,"} & "," & "))) -> 1,0 \% & | R19: =IF(J19="","",CONCATENATE(IF(ResultadosObtidos!G16=ResultadosObtidos!$C16,"\textbf{",""),J19," \% ",IF(ResultadosObtidos!G16=ResultadosObtidos!$C16,"} & "," & "))) -> 1,0 \% & | S19: =IF(K19="","",CONCATENATE(IF(ResultadosObtidos!H16=ResultadosObtidos!$C16,"\textbf{",""),K19," \% ",IF(ResultadosObtidos!H16=ResultadosObtidos!$C16,"} & "," & "))) -> \textbf{0,0 \% } & | T19: =IF(L19="","",CONCATENATE(IF(ResultadosObtidos!I16=ResultadosObtidos!$C16,"\textbf{",""),L19," \% ",IF(ResultadosObtidos!I16=ResultadosObtidos!$C16,"} \\ "," \\ "))) -> 0,3 \% \\
B20: =IF(OR(H20="",I20="",J20="",K20="",L20=""),"LINHA VAZIA OU ERRO EM ALGUMA COLUNA",CONCATENATE(E20," & ",N20,O20,P20,Q20,R20,S20,T20)) -> nome instancia 12 & 32 & 0,0 \% & 0,9 \% & 0,4 \% & \textbf{0,0 \% } & 0,3 \% & 0,7 \% \\ | E20: =ResultadosObtidos!B17 -> nome instancia 12 | F20: =IFERROR(IF(DesvioPercentual!C17<>"",SUBSTITUTE(TEXT(DesvioPercentual!C17,$F$2),".",","),""),"") -> 32 | G20: =IFERROR(IF(DesvioPercentual!D17<>"",SUBSTITUTE(TEXT(DesvioPercentual!D17,$F$3),".",","),""),"") -> 0,0 | H20: =IFERROR(IF(DesvioPercentual!E17<>"",SUBSTITUTE(TEXT(DesvioPercentual!E17,$F$3),".",","),""),"") -> 0,9 | I20: =IFERROR(IF(DesvioPercentual!F17<>"",SUBSTITUTE(TEXT(DesvioPercentual!F17,$F$3),".",","),""),"") -> 0,4 | J20: =IFERROR(IF(DesvioPercentual!G17<>"",SUBSTITUTE(TEXT(DesvioPercentual!G17,$F$3),".",","),""),"") -> 0,0 | K20: =IFERROR(IF(DesvioPercentual!H17<>"",SUBSTITUTE(TEXT(DesvioPercentual!H17,$F$3),".",","),""),"") -> 0,3 | L20: =IFERROR(IF(DesvioPercentual!I17<>"",SUBSTITUTE(TEXT(DesvioPercentual!I17,$F$3),".",","),""),"") -> 0,7 | N20: =CONCATENATE(F20," & ") -> 32 & | O20: =IF(G20="","",CONCATENATE(IF(ResultadosObtidos!D17=ResultadosObtidos!$C17,"\textbf{",""),G20," \% ",IF(ResultadosObtidos!D17=ResultadosObtidos!$C17,"} & "," & "))) -> 0,0 \% & | P20: =IF(H20="","",CONCATENATE(IF(ResultadosObtidos!E17=ResultadosObtidos!$C17,"\textbf{",""),H20," \% ",IF(ResultadosObtidos!E17=ResultadosObtidos!$C17,"} & "," & "))) -> 0,9 \% & | Q20: =IF(I20="","",CONCATENATE(IF(ResultadosObtidos!F17=ResultadosObtidos!$C17,"\textbf{",""),I20," \% ",IF(ResultadosObtidos!F17=ResultadosObtidos!$C17,"} & "," & "))) -> 0,4 \% & | R20: =IF(J20="","",CONCATENATE(IF(ResultadosObtidos!G17=ResultadosObtidos!$C17,"\textbf{",""),J20," \% ",IF(ResultadosObtidos!G17=ResultadosObtidos!$C17,"} & "," & "))) -> \textbf{0,0 \% } & | S20: =IF(K20="","",CONCATENATE(IF(ResultadosObtidos!H17=ResultadosObtidos!$C17,"\textbf{",""),K20," \% ",IF(ResultadosObtidos!H17=ResultadosObtidos!$C17,"} & "," & "))) -> 0,3 \% & | T20: =IF(L20="","",CONCATENATE(IF(ResultadosObtidos!I17=ResultadosObtidos!$C17,"\textbf{",""),L20," \% ",IF(ResultadosObtidos!I17=ResultadosObtidos!$C17,"} \\ "," \\ "))) -> 0,7 \% \\
B21: =IF(OR(H21="",I21="",J21="",K21="",L21=""),"LINHA VAZIA OU ERRO EM ALGUMA COLUNA",CONCATENATE(E21," & ",N21,O21,P21,Q21,R21,S21,T21)) -> nome instancia 13 & 38 & 0,0 \% & 1,0 \% & \textbf{0,0 \% } & 0,7 \% & 0,5 \% & 0,1 \% \\ | E21: =ResultadosObtidos!B18 -> nome instancia 13 | F21: =IFERROR(IF(DesvioPercentual!C18<>"",SUBSTITUTE(TEXT(DesvioPercentual!C18,$F$2),".",","),""),"") -> 38 | G21: =IFERROR(IF(DesvioPercentual!D18<>"",SUBSTITUTE(TEXT(DesvioPercentual!D18,$F$3),".",","),""),"") -> 0,0 | H21: =IFERROR(IF(DesvioPercentual!E18<>"",SUBSTITUTE(TEXT(DesvioPercentual!E18,$F$3),".",","),""),"") -> 1,0 | I21: =IFERROR(IF(DesvioPercentual!F18<>"",SUBSTITUTE(TEXT(DesvioPercentual!F18,$F$3),".",","),""),"") -> 0,0 | J21: =IFERROR(IF(DesvioPercentual!G18<>"",SUBSTITUTE(TEXT(DesvioPercentual!G18,$F$3),".",","),""),"") -> 0,7 | K21: =IFERROR(IF(DesvioPercentual!H18<>"",SUBSTITUTE(TEXT(DesvioPercentual!H18,$F$3),".",","),""),"") -> 0,5 | L21: =IFERROR(IF(DesvioPercentual!I18<>"",SUBSTITUTE(TEXT(DesvioPercentual!I18,$F$3),".",","),""),"") -> 0,1 | N21: =CONCATENATE(F21," & ") -> 38 & | O21: =IF(G21="","",CONCATENATE(IF(ResultadosObtidos!D18=ResultadosObtidos!$C18,"\textbf{",""),G21," \% ",IF(ResultadosObtidos!D18=ResultadosObtidos!$C18,"} & "," & "))) -> 0,0 \% & | P21: =IF(H21="","",CONCATENATE(IF(ResultadosObtidos!E18=ResultadosObtidos!$C18,"\textbf{",""),H21," \% ",IF(ResultadosObtidos!E18=ResultadosObtidos!$C18,"} & "," & "))) -> 1,0 \% & | Q21: =IF(I21="","",CONCATENATE(IF(ResultadosObtidos!F18=ResultadosObtidos!$C18,"\textbf{",""),I21," \% ",IF(ResultadosObtidos!F18=ResultadosObtidos!$C18,"} & "," & "))) -> \textbf{0,0 \% } & | R21: =IF(J21="","",CONCATENATE(IF(ResultadosObtidos!G18=ResultadosObtidos!$C18,"\textbf{",""),J21," \% ",IF(ResultadosObtidos!G18=ResultadosObtidos!$C18,"} & "," & "))) -> 0,7 \% & | S21: =IF(K21="","",CONCATENATE(IF(ResultadosObtidos!H18=ResultadosObtidos!$C18,"\textbf{",""),K21," \% ",IF(ResultadosObtidos!H18=ResultadosObtidos!$C18,"} & "," & "))) -> 0,5 \% & | T21: =IF(L21="","",CONCATENATE(IF(ResultadosObtidos!I18=ResultadosObtidos!$C18,"\textbf{",""),L21," \% ",IF(ResultadosObtidos!I18=ResultadosObtidos!$C18,"} \\ "," \\ "))) -> 0,1 \% \\
... B45: =IF(OR(H45="",I45="",J45="",K45="",L45=""),"LINHA VAZIA OU ERRO EM ALGUMA COLUNA",CONCATENATE(E45," & ",N45,O45,P45,Q45,R45,S45,T45)) -> LINHA VAZIA OU ERRO EM ALGUMA COLUNA | E45: =ResultadosObtidos!B42 | F45: =IFERROR(IF(DesvioPercentual!C42<>"",SUBSTITUTE(TEXT(DesvioPercentual!C42,$F$2),".",","),""),"") | G45: =IFERROR(IF(DesvioPercentual!D42<>"",SUBSTITUTE(TEXT(DesvioPercentual!D42,$F$3),".",","),""),"") | H45: =IFERROR(IF(DesvioPercentual!E42<>"",SUBSTITUTE(TEXT(DesvioPercentual!E42,$F$3),".",","),""),"") | I45: =IFERROR(IF(DesvioPercentual!F42<>"",SUBSTITUTE(TEXT(DesvioPercentual!F42,$F$3),".",","),""),"") | J45: =IFERROR(IF(DesvioPercentual!G42<>"",SUBSTITUTE(TEXT(DesvioPercentual!G42,$F$3),".",","),""),"") | K45: =IFERROR(IF(DesvioPercentual!H42<>"",SUBSTITUTE(TEXT(DesvioPercentual!H42,$F$3),".",","),""),"") | L45: =IFERROR(IF(DesvioPercentual!I42<>"",SUBSTITUTE(TEXT(DesvioPercentual!I42,$F$3),".",","),""),"") | N45: =CONCATENATE(F45," & ") -> & | O45: =IF(G45="","",CONCATENATE(IF(ResultadosObtidos!D42=ResultadosObtidos!$C42,"\textbf{",""),G45," \% ",IF(ResultadosObtidos!D42=ResultadosObtidos!$C42,"} & "," & "))) | P45: =IF(H45="","",CONCATENATE(IF(ResultadosObtidos!E42=ResultadosObtidos!$C42,"\textbf{",""),H45," \% ",IF(ResultadosObtidos!E42=ResultadosObtidos!$C42,"} & "," & "))) | Q45: =IF(I45="","",CONCATENATE(IF(ResultadosObtidos!F42=ResultadosObtidos!$C42,"\textbf{",""),I45," \% ",IF(ResultadosObtidos!F42=ResultadosObtidos!$C42,"} & "," & "))) | R45: =IF(J45="","",CONCATENATE(IF(ResultadosObtidos!G42=ResultadosObtidos!$C42,"\textbf{",""),J45," \% ",IF(ResultadosObtidos!G42=ResultadosObtidos!$C42,"} & "," & "))) | S45: =IF(K45="","",CONCATENATE(IF(ResultadosObtidos!H42=ResultadosObtidos!$C42,"\textbf{",""),K45," \% ",IF(ResultadosObtidos!H42=ResultadosObtidos!$C42,"} & "," & "))) | T45: =IF(L45="","",CONCATENATE(IF(ResultadosObtidos!I42=ResultadosObtidos!$C42,"\textbf{",""),L45," \% ",IF(ResultadosObtidos!I42=ResultadosObtidos!$C42,"} \\ "," \\ ")))
E46: =ResultadosObtidos!B43 | F46: =IFERROR(IF(DesvioPercentual!C43<>"",SUBSTITUTE(TEXT(DesvioPercentual!C43,$F$2),".",","),""),"") | G46: =IFERROR(IF(DesvioPercentual!D43<>"",SUBSTITUTE(TEXT(DesvioPercentual!D43,$F$3),".",","),""),"") | H46: =IFERROR(IF(DesvioPercentual!E43<>"",SUBSTITUTE(TEXT(DesvioPercentual!E43,$F$3),".",","),""),"") | I46: =IFERROR(IF(DesvioPercentual!F43<>"",SUBSTITUTE(TEXT(DesvioPercentual!F43,$F$3),".",","),""),"") | J46: =IFERROR(IF(DesvioPercentual!G43<>"",SUBSTITUTE(TEXT(DesvioPercentual!G43,$F$3),".",","),""),"") | K46: =IFERROR(IF(DesvioPercentual!H43<>"",SUBSTITUTE(TEXT(DesvioPercentual!H43,$F$3),".",","),""),"") | L46: =IFERROR(IF(DesvioPercentual!I43<>"",SUBSTITUTE(TEXT(DesvioPercentual!I43,$F$3),".",","),""),"") | N46: =CONCATENATE(F46," & ") -> & | O46: =IF(G46="","",CONCATENATE(IF(ResultadosObtidos!D43=ResultadosObtidos!$C43,"\textbf{",""),G46," \% ",IF(ResultadosObtidos!D43=ResultadosObtidos!$C43,"} & "," & "))) | P46: =IF(H46="","",CONCATENATE(IF(ResultadosObtidos!E43=ResultadosObtidos!$C43,"\textbf{",""),H46," \% ",IF(ResultadosObtidos!E43=ResultadosObtidos!$C43,"} & "," & "))) | Q46: =IF(I46="","",CONCATENATE(IF(ResultadosObtidos!F43=ResultadosObtidos!$C43,"\textbf{",""),I46," \% ",IF(ResultadosObtidos!F43=ResultadosObtidos!$C43,"} & "," & "))) | R46: =IF(J46="","",CONCATENATE(IF(ResultadosObtidos!G43=ResultadosObtidos!$C43,"\textbf{",""),J46," \% ",IF(ResultadosObtidos!G43=ResultadosObtidos!$C43,"} & "," & "))) | S46: =IF(K46="","",CONCATENATE(IF(ResultadosObtidos!H43=ResultadosObtidos!$C43,"\textbf{",""),K46," \% ",IF(ResultadosObtidos!H43=ResultadosObtidos!$C43,"} & "," & "))) | T46: =IF(L46="","",CONCATENATE(IF(ResultadosObtidos!I43=ResultadosObtidos!$C43,"\textbf{",""),L46," \% ",IF(ResultadosObtidos!I43=ResultadosObtidos!$C43,"} \\ "," \\ ")))
E47: =ResultadosObtidos!B44 | F47: =IFERROR(IF(DesvioPercentual!C44<>"",SUBSTITUTE(TEXT(DesvioPercentual!C44,$F$2),".",","),""),"") | G47: =IFERROR(IF(DesvioPercentual!D44<>"",SUBSTITUTE(TEXT(DesvioPercentual!D44,$F$3),".",","),""),"") | H47: =IFERROR(IF(DesvioPercentual!E44<>"",SUBSTITUTE(TEXT(DesvioPercentual!E44,$F$3),".",","),""),"") | I47: =IFERROR(IF(DesvioPercentual!F44<>"",SUBSTITUTE(TEXT(DesvioPercentual!F44,$F$3),".",","),""),"") | J47: =IFERROR(IF(DesvioPercentual!G44<>"",SUBSTITUTE(TEXT(DesvioPercentual!G44,$F$3),".",","),""),"") | K47: =IFERROR(IF(DesvioPercentual!H44<>"",SUBSTITUTE(TEXT(DesvioPercentual!H44,$F$3),".",","),""),"") | L47: =IFERROR(IF(DesvioPercentual!I44<>"",SUBSTITUTE(TEXT(DesvioPercentual!I44,$F$3),".",","),""),"") | N47: =CONCATENATE(F47," & ") -> & | O47: =IF(G47="","",CONCATENATE(IF(ResultadosObtidos!D44=ResultadosObtidos!$C44,"\textbf{",""),G47," \% ",IF(ResultadosObtidos!D44=ResultadosObtidos!$C44,"} & "," & "))) | P47: =IF(H47="","",CONCATENATE(IF(ResultadosObtidos!E44=ResultadosObtidos!$C44,"\textbf{",""),H47," \% ",IF(ResultadosObtidos!E44=ResultadosObtidos!$C44,"} & "," & "))) | Q47: =IF(I47="","",CONCATENATE(IF(ResultadosObtidos!F44=ResultadosObtidos!$C44,"\textbf{",""),I47," \% ",IF(ResultadosObtidos!F44=ResultadosObtidos!$C44,"} & "," & "))) | R47: =IF(J47="","",CONCATENATE(IF(ResultadosObtidos!G44=ResultadosObtidos!$C44,"\textbf{",""),J47," \% ",IF(ResultadosObtidos!G44=ResultadosObtidos!$C44,"} & "," & "))) | S47: =IF(K47="","",CONCATENATE(IF(ResultadosObtidos!H44=ResultadosObtidos!$C44,"\textbf{",""),K47," \% ",IF(ResultadosObtidos!H44=ResultadosObtidos!$C44,"} & "," & "))) | T47: =IF(L47="","",CONCATENATE(IF(ResultadosObtidos!I44=ResultadosObtidos!$C44,"\textbf{",""),L47," \% ",IF(ResultadosObtidos!I44=ResultadosObtidos!$C44,"} \\ "," \\ ")))
E48: =ResultadosObtidos!B45 | F48: =IFERROR(IF(DesvioPercentual!C45<>"",SUBSTITUTE(TEXT(DesvioPercentual!C45,$F$2),".",","),""),"") | G48: =IFERROR(IF(DesvioPercentual!D45<>"",SUBSTITUTE(TEXT(DesvioPercentual!D45,$F$3),".",","),""),"") | H48: =IFERROR(IF(DesvioPercentual!E45<>"",SUBSTITUTE(TEXT(DesvioPercentual!E45,$F$3),".",","),""),"") | I48: =IFERROR(IF(DesvioPercentual!F45<>"",SUBSTITUTE(TEXT(DesvioPercentual!F45,$F$3),".",","),""),"") | J48: =IFERROR(IF(DesvioPercentual!G45<>"",SUBSTITUTE(TEXT(DesvioPercentual!G45,$F$3),".",","),""),"") | K48: =IFERROR(IF(DesvioPercentual!H45<>"",SUBSTITUTE(TEXT(DesvioPercentual!H45,$F$3),".",","),""),"") | L48: =IFERROR(IF(DesvioPercentual!I45<>"",SUBSTITUTE(TEXT(DesvioPercentual!I45,$F$3),".",","),""),"") | N48: =CONCATENATE(F48," & ") -> & | O48: =IF(G48="","",CONCATENATE(IF(ResultadosObtidos!D45=ResultadosObtidos!$C45,"\textbf{",""),G48," \% ",IF(ResultadosObtidos!D45=ResultadosObtidos!$C45,"} & "," & "))) | P48: =IF(H48="","",CONCATENATE(IF(ResultadosObtidos!E45=ResultadosObtidos!$C45,"\textbf{",""),H48," \% ",IF(ResultadosObtidos!E45=ResultadosObtidos!$C45,"} & "," & "))) | Q48: =IF(I48="","",CONCATENATE(IF(ResultadosObtidos!F45=ResultadosObtidos!$C45,"\textbf{",""),I48," \% ",IF(ResultadosObtidos!F45=ResultadosObtidos!$C45,"} & "," & "))) | R48: =IF(J48="","",CONCATENATE(IF(ResultadosObtidos!G45=ResultadosObtidos!$C45,"\textbf{",""),J48," \% ",IF(ResultadosObtidos!G45=ResultadosObtidos!$C45,"} & "," & "))) | S48: =IF(K48="","",CONCATENATE(IF(ResultadosObtidos!H45=ResultadosObtidos!$C45,"\textbf{",""),K48," \% ",IF(ResultadosObtidos!H45=ResultadosObtidos!$C45,"} & "," & "))) | T48: =IF(L48="","",CONCATENATE(IF(ResultadosObtidos!I45=ResultadosObtidos!$C45,"\textbf{",""),L48," \% ",IF(ResultadosObtidos!I45=ResultadosObtidos!$C45,"} \\ "," \\ ")))
E49: =ResultadosObtidos!B46 | F49: =IFERROR(IF(DesvioPercentual!C46<>"",SUBSTITUTE(TEXT(DesvioPercentual!C46,$F$2),".",","),""),"") | G49: =IFERROR(IF(DesvioPercentual!D46<>"",SUBSTITUTE(TEXT(DesvioPercentual!D46,$F$3),".",","),""),"") | H49: =IFERROR(IF(DesvioPercentual!E46<>"",SUBSTITUTE(TEXT(DesvioPercentual!E46,$F$3),".",","),""),"") | I49: =IFERROR(IF(DesvioPercentual!F46<>"",SUBSTITUTE(TEXT(DesvioPercentual!F46,$F$3),".",","),""),"") | J49: =IFERROR(IF(DesvioPercentual!G46<>"",SUBSTITUTE(TEXT(DesvioPercentual!G46,$F$3),".",","),""),"") | K49: =IFERROR(IF(DesvioPercentual!H46<>"",SUBSTITUTE(TEXT(DesvioPercentual!H46,$F$3),".",","),""),"") | L49: =IFERROR(IF(DesvioPercentual!I46<>"",SUBSTITUTE(TEXT(DesvioPercentual!I46,$F$3),".",","),""),"") | N49: =CONCATENATE(F49," & ") -> & | O49: =IF(G49="","",CONCATENATE(IF(ResultadosObtidos!D46=ResultadosObtidos!$C46,"\textbf{",""),G49," \% ",IF(ResultadosObtidos!D46=ResultadosObtidos!$C46,"} & "," & "))) | P49: =IF(H49="","",CONCATENATE(IF(ResultadosObtidos!E46=ResultadosObtidos!$C46,"\textbf{",""),H49," \% ",IF(ResultadosObtidos!E46=ResultadosObtidos!$C46,"} & "," & "))) | Q49: =IF(I49="","",CONCATENATE(IF(ResultadosObtidos!F46=ResultadosObtidos!$C46,"\textbf{",""),I49," \% ",IF(ResultadosObtidos!F46=ResultadosObtidos!$C46,"} & "," & "))) | R49: =IF(J49="","",CONCATENATE(IF(ResultadosObtidos!G46=ResultadosObtidos!$C46,"\textbf{",""),J49," \% ",IF(ResultadosObtidos!G46=ResultadosObtidos!$C46,"} & "," & "))) | S49: =IF(K49="","",CONCATENATE(IF(ResultadosObtidos!H46=ResultadosObtidos!$C46,"\textbf{",""),K49," \% ",IF(ResultadosObtidos!H46=ResultadosObtidos!$C46,"} & "," & "))) | T49: =IF(L49="","",CONCATENATE(IF(ResultadosObtidos!I46=ResultadosObtidos!$C46,"\textbf{",""),L49," \% ",IF(ResultadosObtidos!I46=ResultadosObtidos!$C46,"} \\ "," \\ ")))
E50: =ResultadosObtidos!B47 | F50: =IFERROR(IF(DesvioPercentual!C47<>"",SUBSTITUTE(TEXT(DesvioPercentual!C47,$F$2),".",","),""),"") | G50: =IFERROR(IF(DesvioPercentual!D47<>"",SUBSTITUTE(TEXT(DesvioPercentual!D47,$F$3),".",","),""),"") | H50: =IFERROR(IF(DesvioPercentual!E47<>"",SUBSTITUTE(TEXT(DesvioPercentual!E47,$F$3),".",","),""),"") | I50: =IFERROR(IF(DesvioPercentual!F47<>"",SUBSTITUTE(TEXT(DesvioPercentual!F47,$F$3),".",","),""),"") | J50: =IFERROR(IF(DesvioPercentual!G47<>"",SUBSTITUTE(TEXT(DesvioPercentual!G47,$F$3),".",","),""),"") | K50: =IFERROR(IF(DesvioPercentual!H47<>"",SUBSTITUTE(TEXT(DesvioPercentual!H47,$F$3),".",","),""),"") | L50: =IFERROR(IF(DesvioPercentual!I47<>"",SUBSTITUTE(TEXT(DesvioPercentual!I47,$F$3),".",","),""),"") | N50: =CONCATENATE(F50," & ") -> & | O50: =IF(G50="","",CONCATENATE(IF(ResultadosObtidos!D47=ResultadosObtidos!$C47,"\textbf{",""),G50," \% ",IF(ResultadosObtidos!D47=ResultadosObtidos!$C47,"} & "," & "))) | P50: =IF(H50="","",CONCATENATE(IF(ResultadosObtidos!E47=ResultadosObtidos!$C47,"\textbf{",""),H50," \% ",IF(ResultadosObtidos!E47=ResultadosObtidos!$C47,"} & "," & "))) | Q50: =IF(I50="","",CONCATENATE(IF(ResultadosObtidos!F47=ResultadosObtidos!$C47,"\textbf{",""),I50," \% ",IF(ResultadosObtidos!F47=ResultadosObtidos!$C47,"} & "," & "))) | R50: =IF(J50="","",CONCATENATE(IF(ResultadosObtidos!G47=ResultadosObtidos!$C47,"\textbf{",""),J50," \% ",IF(ResultadosObtidos!G47=ResultadosObtidos!$C47,"} & "," & "))) | S50: =IF(K50="","",CONCATENATE(IF(ResultadosObtidos!H47=ResultadosObtidos!$C47,"\textbf{",""),K50," \% ",IF(ResultadosObtidos!H47=ResultadosObtidos!$C47,"} & "," & "))) | T50: =IF(L50="","",CONCATENATE(IF(ResultadosObtidos!I47=ResultadosObtidos!$C47,"\textbf{",""),L50," \% ",IF(ResultadosObtidos!I47=ResultadosObtidos!$C47,"} \\ "," \\ ")))
E51: =ResultadosObtidos!B48 | F51: =IFERROR(IF(DesvioPercentual!C48<>"",SUBSTITUTE(TEXT(DesvioPercentual!C48,$F$2),".",","),""),"") | G51: =IFERROR(IF(DesvioPercentual!D48<>"",SUBSTITUTE(TEXT(DesvioPercentual!D48,$F$3),".",","),""),"") | H51: =IFERROR(IF(DesvioPercentual!E48<>"",SUBSTITUTE(TEXT(DesvioPercentual!E48,$F$3),".",","),""),"") | I51: =IFERROR(IF(DesvioPercentual!F48<>"",SUBSTITUTE(TEXT(DesvioPercentual!F48,$F$3),".",","),""),"") | J51: =IFERROR(IF(DesvioPercentual!G48<>"",SUBSTITUTE(TEXT(DesvioPercentual!G48,$F$3),".",","),""),"") | K51: =IFERROR(IF(DesvioPercentual!H48<>"",SUBSTITUTE(TEXT(DesvioPercentual!H48,$F$3),".",","),""),"") | L51: =IFERROR(IF(DesvioPercentual!I48<>"",SUBSTITUTE(TEXT(DesvioPercentual!I48,$F$3),".",","),""),"") | N51: =CONCATENATE(F51," & ") -> & | O51: =IF(G51="","",CONCATENATE(IF(ResultadosObtidos!D48=ResultadosObtidos!$C48,"\textbf{",""),G51," \% ",IF(ResultadosObtidos!D48=ResultadosObtidos!$C48,"} & "," & "))) | P51: =IF(H51="","",CONCATENATE(IF(ResultadosObtidos!E48=ResultadosObtidos!$C48,"\textbf{",""),H51," \% ",IF(ResultadosObtidos!E48=ResultadosObtidos!$C48,"} & "," & "))) | Q51: =IF(I51="","",CONCATENATE(IF(ResultadosObtidos!F48=ResultadosObtidos!$C48,"\textbf{",""),I51," \% ",IF(ResultadosObtidos!F48=ResultadosObtidos!$C48,"} & "," & "))) | R51: =IF(J51="","",CONCATENATE(IF(ResultadosObtidos!G48=ResultadosObtidos!$C48,"\textbf{",""),J51," \% ",IF(ResultadosObtidos!G48=ResultadosObtidos!$C48,"} & "," & "))) | S51: =IF(K51="","",CONCATENATE(IF(ResultadosObtidos!H48=ResultadosObtidos!$C48,"\textbf{",""),K51," \% ",IF(ResultadosObtidos!H48=ResultadosObtidos!$C48,"} & "," & "))) | T51: =IF(L51="","",CONCATENATE(IF(ResultadosObtidos!I48=ResultadosObtidos!$C48,"\textbf{",""),L51," \% ",IF(ResultadosObtidos!I48=ResultadosObtidos!$C48,"} \\ "," \\ ")))
E52: =ResultadosObtidos!B49 | F52: =IFERROR(IF(DesvioPercentual!C49<>"",SUBSTITUTE(TEXT(DesvioPercentual!C49,$F$2),".",","),""),"") | G52: =IFERROR(IF(DesvioPercentual!D49<>"",SUBSTITUTE(TEXT(DesvioPercentual!D49,$F$3),".",","),""),"") | H52: =IFERROR(IF(DesvioPercentual!E49<>"",SUBSTITUTE(TEXT(DesvioPercentual!E49,$F$3),".",","),""),"") | I52: =IFERROR(IF(DesvioPercentual!F49<>"",SUBSTITUTE(TEXT(DesvioPercentual!F49,$F$3),".",","),""),"") | J52: =IFERROR(IF(DesvioPercentual!G49<>"",SUBSTITUTE(TEXT(DesvioPercentual!G49,$F$3),".",","),""),"") | K52: =IFERROR(IF(DesvioPercentual!H49<>"",SUBSTITUTE(TEXT(DesvioPercentual!H49,$F$3),".",","),""),"") | L52: =IFERROR(IF(DesvioPercentual!I49<>"",SUBSTITUTE(TEXT(DesvioPercentual!I49,$F$3),".",","),""),"") | N52: =CONCATENATE(F52," & ") -> & | O52: =IF(G52="","",CONCATENATE(IF(ResultadosObtidos!D49=ResultadosObtidos!$C49,"\textbf{",""),G52," \% ",IF(ResultadosObtidos!D49=ResultadosObtidos!$C49,"} & "," & "))) | P52: =IF(H52="","",CONCATENATE(IF(ResultadosObtidos!E49=ResultadosObtidos!$C49,"\textbf{",""),H52," \% ",IF(ResultadosObtidos!E49=ResultadosObtidos!$C49,"} & "," & "))) | Q52: =IF(I52="","",CONCATENATE(IF(ResultadosObtidos!F49=ResultadosObtidos!$C49,"\textbf{",""),I52," \% ",IF(ResultadosObtidos!F49=ResultadosObtidos!$C49,"} & "," & "))) | R52: =IF(J52="","",CONCATENATE(IF(ResultadosObtidos!G49=ResultadosObtidos!$C49,"\textbf{",""),J52," \% ",IF(ResultadosObtidos!G49=ResultadosObtidos!$C49,"} & "," & "))) | S52: =IF(K52="","",CONCATENATE(IF(ResultadosObtidos!H49=ResultadosObtidos!$C49,"\textbf{",""),K52," \% ",IF(ResultadosObtidos!H49=ResultadosObtidos!$C49,"} & "," & "))) | T52: =IF(L52="","",CONCATENATE(IF(ResultadosObtidos!I49=ResultadosObtidos!$C49,"\textbf{",""),L52," \% ",IF(ResultadosObtidos!I49=ResultadosObtidos!$C49,"} \\ "," \\ ")))
E53: =ResultadosObtidos!B50 | F53: =IFERROR(IF(DesvioPercentual!C50<>"",SUBSTITUTE(TEXT(DesvioPercentual!C50,$F$2),".",","),""),"") | G53: =IFERROR(IF(DesvioPercentual!D50<>"",SUBSTITUTE(TEXT(DesvioPercentual!D50,$F$3),".",","),""),"") | H53: =IFERROR(IF(DesvioPercentual!E50<>"",SUBSTITUTE(TEXT(DesvioPercentual!E50,$F$3),".",","),""),"") | I53: =IFERROR(IF(DesvioPercentual!F50<>"",SUBSTITUTE(TEXT(DesvioPercentual!F50,$F$3),".",","),""),"") | J53: =IFERROR(IF(DesvioPercentual!G50<>"",SUBSTITUTE(TEXT(DesvioPercentual!G50,$F$3),".",","),""),"") | K53: =IFERROR(IF(DesvioPercentual!H50<>"",SUBSTITUTE(TEXT(DesvioPercentual!H50,$F$3),".",","),""),"") | L53: =IFERROR(IF(DesvioPercentual!I50<>"",SUBSTITUTE(TEXT(DesvioPercentual!I50,$F$3),".",","),""),"") | N53: =CONCATENATE(F53," & ") -> & | O53: =IF(G53="","",CONCATENATE(IF(ResultadosObtidos!D50=ResultadosObtidos!$C50,"\textbf{",""),G53," \% ",IF(ResultadosObtidos!D50=ResultadosObtidos!$C50,"} & "," & "))) | P53: =IF(H53="","",CONCATENATE(IF(ResultadosObtidos!E50=ResultadosObtidos!$C50,"\textbf{",""),H53," \% ",IF(ResultadosObtidos!E50=ResultadosObtidos!$C50,"} & "," & "))) | Q53: =IF(I53="","",CONCATENATE(IF(ResultadosObtidos!F50=ResultadosObtidos!$C50,"\textbf{",""),I53," \% ",IF(ResultadosObtidos!F50=ResultadosObtidos!$C50,"} & "," & "))) | R53: =IF(J53="","",CONCATENATE(IF(ResultadosObtidos!G50=ResultadosObtidos!$C50,"\textbf{",""),J53," \% ",IF(ResultadosObtidos!G50=ResultadosObtidos!$C50,"} & "," & "))) | S53: =IF(K53="","",CONCATENATE(IF(ResultadosObtidos!H50=ResultadosObtidos!$C50,"\textbf{",""),K53," \% ",IF(ResultadosObtidos!H50=ResultadosObtidos!$C50,"} & "," & "))) | T53: =IF(L53="","",CONCATENATE(IF(ResultadosObtidos!I50=ResultadosObtidos!$C50,"\textbf{",""),L53," \% ",IF(ResultadosObtidos!I50=ResultadosObtidos!$C50,"} \\ "," \\ ")))
E54: =ResultadosObtidos!B51 | F54: =IFERROR(IF(DesvioPercentual!C51<>"",SUBSTITUTE(TEXT(DesvioPercentual!C51,$F$2),".",","),""),"") | G54: =IFERROR(IF(DesvioPercentual!D51<>"",SUBSTITUTE(TEXT(DesvioPercentual!D51,$F$3),".",","),""),"") | H54: =IFERROR(IF(DesvioPercentual!E51<>"",SUBSTITUTE(TEXT(DesvioPercentual!E51,$F$3),".",","),""),"") | I54: =IFERROR(IF(DesvioPercentual!F51<>"",SUBSTITUTE(TEXT(DesvioPercentual!F51,$F$3),".",","),""),"") | J54: =IFERROR(IF(DesvioPercentual!G51<>"",SUBSTITUTE(TEXT(DesvioPercentual!G51,$F$3),".",","),""),"") | K54: =IFERROR(IF(DesvioPercentual!H51<>"",SUBSTITUTE(TEXT(DesvioPercentual!H51,$F$3),".",","),""),"") | L54: =IFERROR(IF(DesvioPercentual!I51<>"",SUBSTITUTE(TEXT(DesvioPercentual!I51,$F$3),".",","),""),"") | N54: =CONCATENATE(F54," & ") -> & | O54: =IF(G54="","",CONCATENATE(IF(ResultadosObtidos!D51=ResultadosObtidos!$C51,"\textbf{",""),G54," \% ",IF(ResultadosObtidos!D51=ResultadosObtidos!$C51,"} & "," & "))) | P54: =IF(H54="","",CONCATENATE(IF(ResultadosObtidos!E51=ResultadosObtidos!$C51,"\textbf{",""),H54," \% ",IF(ResultadosObtidos!E51=ResultadosObtidos!$C51,"} & "," & "))) | Q54: =IF(I54="","",CONCATENATE(IF(ResultadosObtidos!F51=ResultadosObtidos!$C51,"\textbf{",""),I54," \% ",IF(ResultadosObtidos!F51=ResultadosObtidos!$C51,"} & "," & "))) | R54: =IF(J54="","",CONCATENATE(IF(ResultadosObtidos!G51=ResultadosObtidos!$C51,"\textbf{",""),J54," \% ",IF(ResultadosObtidos!G51=ResultadosObtidos!$C51,"} & "," & "))) | S54: =IF(K54="","",CONCATENATE(IF(ResultadosObtidos!H51=ResultadosObtidos!$C51,"\textbf{",""),K54," \% ",IF(ResultadosObtidos!H51=ResultadosObtidos!$C51,"} & "," & "))) | T54: =IF(L54="","",CONCATENATE(IF(ResultadosObtidos!I51=ResultadosObtidos!$C51,"\textbf{",""),L54," \% ",IF(ResultadosObtidos!I51=ResultadosObtidos!$C51,"} \\ "," \\ ")))
